[2024-03-22T18:55:03.185+0000] {taskinstance.py:1171} INFO - Dependencies all met for <TaskInstance: milestone3.clean_data scheduled__2024-03-22T18:54:00+00:00 [queued]>
[2024-03-22T18:55:03.190+0000] {taskinstance.py:1171} INFO - Dependencies all met for <TaskInstance: milestone3.clean_data scheduled__2024-03-22T18:54:00+00:00 [queued]>
[2024-03-22T18:55:03.190+0000] {taskinstance.py:1368} INFO - 
--------------------------------------------------------------------------------
[2024-03-22T18:55:03.191+0000] {taskinstance.py:1369} INFO - Starting attempt 1 of 2
[2024-03-22T18:55:03.191+0000] {taskinstance.py:1370} INFO - 
--------------------------------------------------------------------------------
[2024-03-22T18:55:03.198+0000] {taskinstance.py:1389} INFO - Executing <Task(PythonOperator): clean_data> on 2024-03-22 18:54:00+00:00
[2024-03-22T18:55:03.204+0000] {standard_task_runner.py:52} INFO - Started process 1993 to run task
[2024-03-22T18:55:03.208+0000] {standard_task_runner.py:79} INFO - Running: ['***', 'tasks', 'run', 'milestone3', 'clean_data', 'scheduled__2024-03-22T18:54:00+00:00', '--job-id', '224', '--raw', '--subdir', 'DAGS_FOLDER/P2M3_elia_DAG.py', '--cfg-path', '/tmp/tmpgc9pec3d', '--error-file', '/tmp/tmpv2njjfsa']
[2024-03-22T18:55:03.209+0000] {standard_task_runner.py:80} INFO - Job 224: Subtask clean_data
[2024-03-22T18:55:03.268+0000] {task_command.py:371} INFO - Running <TaskInstance: milestone3.clean_data scheduled__2024-03-22T18:54:00+00:00 [running]> on host b79cb602ca97
[2024-03-22T18:55:03.325+0000] {taskinstance.py:1583} INFO - Exporting the following env vars:
AIRFLOW_CTX_DAG_OWNER=elia
AIRFLOW_CTX_DAG_ID=milestone3
AIRFLOW_CTX_TASK_ID=clean_data
AIRFLOW_CTX_EXECUTION_DATE=2024-03-22T18:54:00+00:00
AIRFLOW_CTX_TRY_NUMBER=1
AIRFLOW_CTX_DAG_RUN_ID=scheduled__2024-03-22T18:54:00+00:00
[2024-03-22T18:55:03.421+0000] {logging_mixin.py:115} INFO -    index      Date    Year     Month  ...  Unit Price   Cost Revenue Column1
0      0  02/19/16  2016.0  February  ...  109.000000   80.0   109.0     NaN
1      1  02/20/16  2016.0  February  ...   28.500000   49.0    57.0     NaN
2      2  02/27/16  2016.0  February  ...    5.000000   11.0    15.0     NaN
3      3  03/12/16  2016.0     March  ...  116.500000  175.0   233.0     NaN
4      4  03/12/16  2016.0     March  ...   41.666667  105.0   125.0     NaN

[5 rows x 16 columns]
[2024-03-22T18:55:03.448+0000] {logging_mixin.py:115} INFO -    index      Date    Year     Month  ...  Unit Price   Cost Revenue Column1
0      0  02/19/16  2016.0  February  ...  109.000000   80.0   109.0     NaN
1      1  02/20/16  2016.0  February  ...   28.500000   49.0    57.0     NaN
2      2  02/27/16  2016.0  February  ...    5.000000   11.0    15.0     NaN
3      3  03/12/16  2016.0     March  ...  116.500000  175.0   233.0     NaN
4      4  03/12/16  2016.0     March  ...   41.666667  105.0   125.0     NaN

[5 rows x 16 columns]
[2024-03-22T18:55:03.455+0000] {taskinstance.py:1902} ERROR - Task failed with exception
Traceback (most recent call last):
  File "/home/airflow/.local/lib/python3.7/site-packages/pandas/core/indexes/base.py", line 3361, in get_loc
    return self._engine.get_loc(casted_key)
  File "pandas/_libs/index.pyx", line 76, in pandas._libs.index.IndexEngine.get_loc
  File "pandas/_libs/index.pyx", line 108, in pandas._libs.index.IndexEngine.get_loc
  File "pandas/_libs/hashtable_class_helper.pxi", line 5198, in pandas._libs.hashtable.PyObjectHashTable.get_item
  File "pandas/_libs/hashtable_class_helper.pxi", line 5206, in pandas._libs.hashtable.PyObjectHashTable.get_item
KeyError: 'age'

The above exception was the direct cause of the following exception:

Traceback (most recent call last):
  File "/home/airflow/.local/lib/python3.7/site-packages/airflow/operators/python.py", line 171, in execute
    return_value = self.execute_callable()
  File "/home/airflow/.local/lib/python3.7/site-packages/airflow/operators/python.py", line 189, in execute_callable
    return self.python_callable(*self.op_args, **self.op_kwargs)
  File "/opt/airflow/dags/P2M3_elia_DAG.py", line 55, in clean
    df['age'] = df['age'].astype(int)
  File "/home/airflow/.local/lib/python3.7/site-packages/pandas/core/frame.py", line 3458, in __getitem__
    indexer = self.columns.get_loc(key)
  File "/home/airflow/.local/lib/python3.7/site-packages/pandas/core/indexes/base.py", line 3363, in get_loc
    raise KeyError(key) from err
KeyError: 'age'
[2024-03-22T18:55:03.467+0000] {taskinstance.py:1412} INFO - Marking task as UP_FOR_RETRY. dag_id=milestone3, task_id=clean_data, execution_date=20240322T185400, start_date=20240322T185503, end_date=20240322T185503
[2024-03-22T18:55:03.479+0000] {standard_task_runner.py:97} ERROR - Failed to execute job 224 for task clean_data ('age'; 1993)
[2024-03-22T18:55:03.516+0000] {local_task_job.py:156} INFO - Task exited with return code 1
[2024-03-22T18:55:03.555+0000] {local_task_job.py:279} INFO - 0 downstream tasks scheduled from follow-on schedule check
